<mujoco>
    <worldbody>
        <body name="zeus_car" pos="0 0 0.1">

            <joint name="car_slider_x" type="slide" pos="0 0 0" axis="1 0 0"/>
            <joint name="car_slider_y" type="slide" pos="0 0 0" axis="0 1 0"/>
            <joint name="car_hinge" type="hinge" pos="0 0 0" axis="0 0 1"/>

            <geom name="car_mesh" type="mesh" mesh="zeus_car_mesh" material="zeus_car_material" pos="0 0 0.06" xyaxes="1 0 0 0 1 0"/> 

            <body name="target" pos="0 0 0.13">

                <!-- <geom name="calibration_box" pos="0 0 0" type="box" size="0.055 0.08 0.01" rgba="0.655 0.820 0.212 0.500"/> -->
                <geom pos="0 0 0.0075" size="0.1 0.005" type="cylinder" rgba="0.178235 0.566471 0.229216 1.0" />
                <geom name="target_top" pos="0 0 0" type="box" size="0.09 0.09 0.0025"  material="aluminum" contype="1"/>
                <geom name="target_left" pos="0 0.055 -0.053" type="box" size="0.015 0.0025 0.0555" material="aluminum"/>
                <geom name="target_right" pos="0 -0.055 -0.053" type="box" size="0.015 0.0025 0.0555" material="aluminum"/>

            </body>

        </body>
    </worldbody>
</mujoco> 

